Workbook

Sheet FORPTB13
J1: Acompanhamento de Rejeitos no Processo | N1: TTL | O1: =SUBTOTAL(9,O4:O999999) -> 0 | Q1: QUEM GEROU O SCRAP ? | U1: FORPTB -13 Data: 17 / 11 / 2025
B3: DATA | C3: SEM | D3: TURNO | E3: LINHA - AREA | F3: LIDER | G3: PQC | H3: MODELO | I3: QTDE | J3: ITEM | K3: STATUS | L3: CÓDIGO | M3: DESCRIÇÃO | N3: V UNIT | O3: VALOR TT | P3: MODELO USADO | Q3: RESPONSÁVEL | R3: ESTAÇÃO | S3: MOTIVO/POSMEC | T3: CAUSA RAIZ | U3: CONTRA MEDIDA

Sheet Dados
A2: TURNO | B2: LINHA-AREA | D2: MODELO | F2: LIDER | H2: QUALIDADE | J2: ITEM | L2: STATUS | N2: CODIGO | O2: MODELO | P2: DESCRIÇÃO | Q2: DESCRIÇÃO2 | R2: PLANT | S2: VALOR | U2: OPERADOR | V2: ESTAÇÃO | X2: CAUSA RAIZ | Z2: MOTIVO | AB2: CONTRA MEDIDA
A3: 1 TURNO | B3: SEC01 | D3: SM-X306B/128G ( GREEN ) | F3: ADRIANA | H3: AMANDA COELHO | J3: BATERIA | L3: RMA | N3: 6001-003630 | O3: X230_X236 | P3: PARAFUSO, DE ACO. | S3: 0.02 | X3: MAQUINA
A4: 2 TURNO | B4: SEC02 | D4: SM-X400/128G ( GRAY ) | F4: ERY ROOL | H4: ANA PAULA LEDESMA | J4: PLACA | L4: TRILHA ROMPIDA | N4: GH02-25161A | O4: X230_X236 | P4: TIRA DE PLASTICO, AUTO-ADESIVA. | S4: 0.17 | X4: OPERACIONAL
B5: SEC03 | D5: SM-X400/256G ( GRAY ) | F5: HERCULES | H5: FRANCISCA BATISTA | J5: FRONT | L5: EXCESSO RETRABALHO | N5: GH02-27857A | O5: X230_X236 | P5: TIRA DE LIGA DE COBRE, AUTO-ADESIVO. | S5: 0.05 | X5: MATERIAL
B6: TNP01 | D6: SM-X406B/128G ( GRAY ) | F6: JARLISON | H6: JACIMEIRE DE OLIVEIRA | J6: REAR | L6: QUEBRADO | N6: GH02-27858A | O6: X230_X236 | P6: TECIDO EM TIRA, COM UMA DAS FACES COM SU | S6: 0.01 | X6: MATERIAL-FORNECEDOR
B7: TNP02 | D7: SM-X406B/256G ( GRAY ) | F7: LEOPOLDO | H7: LARISSA GEOVANA | J7: CAMERA | L7: ALTERADO | N7: GH39-01742A | O7: SM-X730 | P7: CONDUTOR ELETRICO COAXIAL, PARA USO EM A | Q7: CABO VERM. | R7: P81L | S7: 0.34 | X7: METODO
B8: TNP03 | D8: SM-X400B/128G ( RED ) | F8: MILER | H8: PAULO SAMUEL | J8: CONECTOR | L8: BATIDO | N8: GH39-01919A | O8: SM-X620/X626 | P8: CABO COAXIAL COM PECAS DE CONEXAO. | Q8: CABO COAXIAL | R8: P81L | S8: 0.4
B9: REPARO | D9: SM-X730/256G ( GRAY ) | F9: M MACHADO | J9: CABOS | L9: DANIFICADO | N9: GH39-02149A | O9: SM-X510/X516 | P9: CABO COAXIAL COM PECAS DE CONEXAO. | Q9: CABO COAX | S9: 0.38
B10: RETRABALHO | D10: SM-X736B/256G ( GRAY ) | F10: ROBERTA | J10: OUTRO(S) | L10: RISCADO | N10: GH39-02183A | O10: SM-X520/X526 | P10: CIRCUITO IMPRESSO DUPLA FACE, FLEXIVEL, | Q10: CABO COAXIAL | R10: P81L | S10: 0.4
D11: SM-X930/512G ( GRAY ) | F11: SABRINA | J11: MIUDEZA(S) | N11: GH39-02192A | O11: X236 | P11: CABO COAXIAL COM PECAS DE CONEXAO. | S11: 0.35
D12: SM-P620/64G ( GRAY ) | F12: SANDRINE | N12: GH39-02193A | O12: X236 | P12: CABO COAXIAL COM PECAS DE CONEXAO. | S12: 0.36
D13: SM-P620/64G ( PINK ) | F13: SILVIA VALENTE | N13: GH39-02194A | O13: X236 | P13: CABO COAXIAL COM PECAS DE CONEXAO. | S13: 0.38
D14: SM-P625/64G ( GRAY ) | F14: RAFAEL SILVA | N14: GH39-02195A | O14: X236 | P14: CABO COAXIAL COM PECAS DE CONEXAO. | S14: 0.35
D15: SM-P625/128G ( GRAY ) | F15: STARLEM | N15: GH43-05228B | O15: SM-X620/X626 | P15: ACUMULADOR ELETRICO DE ION-LITIO, RECARR | Q15: BATERIA | R15: P81L | S15: 66.88
D16: SM-X820 /256 (GRAY) | F16: VANDA | N16: GH43-05266C | O16: SM-X400/SM-X406/SM-X520/SM-X526 | P16: ACUMULADOR ELETRICO DE ION-LITIO, RECARR | Q16: BATERIA | R16: P81L | S16: 98.87
D17: SM-X820/512 (GRAY) | F17: CARLOS B | N17: GH59-15356A | O17: SM-X306/T575 | P17: CIRCUITO IMPRESSO DUPLA FACE, FLEXIVEL, | Q17: 0 | S17: 7.24
D18: SM-X520/128G ( LIGHT BLUE ) | N18: GH59-15701A | O18: SM-X510/X400 | P18: CIRCUITO IMPRESSO MULTICAMADAS, SEM COMP | Q18: CABO FLAT P | S18: 1.98
D19: SM-X520/128G ( GRAY ) | N19: GH59-15702A | O19: SM-X510 | P19: CIRCUITO IMPRESSO DUPLA FACE, FLEXIVEL, | Q19: CABO FLAT | S19: 9.52
D20: SM-X520/128G ( SILVER ) | N20: GH59-15792A | O20: SM-X820 | P20: CIRCUITO IMPRESSO DUPLA FACE, FLEXIVEL | Q20: CABO FLAT | S20: 9.01
D21: SM-X526B/128G ( LIGHT BLUE ) | N21: GH59-15871A | O21: SM-X620/X626 | P21: CIRCUITO IMPRESSO DUPLA FACE, FLEXIVEL, | Q21: CABO FLAT | S21: 2.78
D22: SM-X526B/128G ( GRAY ) | N22: GH59-15876A | O22: SM-X520/X526 | P22: CIRCUITO IMPRESSO DUPLA FACE, FLEXIVEL, | Q22: CABO FLAT | S22: 10.01
D23: SM-X526B/128G ( SILVER ) | N23: GH59-15877A | O23: SM-X620/X626 | P23: CIRCUITO IMPRESSO DUPLA FACE, FLEXIVEL, | Q23: CABO FLAT | R23: P81L | S23: 11.38
D24: SM-X620/128G ( LIGHT BLUE ) | N24: GH59-15883A | O24: SM-X520/X526 | P24: CIRCUITO IMPRESSO DUPLA FACE, FLEXIVEL, | Q24: CABO FLAT P | S24: 2.44
D25: SM-X620/128G ( GRAY ) | N25: GH61-19224A | O25: SM-X820 | P25: SUPORTE DE PLASTICO | Q25: BRACKET P | S25: 0.71
D26: SM-X620/128G ( SILVER ) | N26: GH61-21465A | O26: X230_X236 | P26: SUPORTE ESTAMPADO, DE ACO. | S26: 0.11
D27: SM-X626B/128G ( LIGHT BLUE ) | N27: GH61-21467A | O27: X230_X236 | P27: SUPORTE ESTAMPADO, DE ACO. | S27: 0.08
D28: SM-X626B/128G ( GRAY ) | N28: GH63-20834A | O28: SM-X306 | P28: TIRA DE PLASTICO, AUTO-ADESIVA. | Q28: 0 | S28: 0.06
D29: SM-X626B/128G ( SILVER ) | N29: GH63-21644A | O29: SM-X306 | P29: TIRA DE PLASTICO, AUTO-ADESIVA. | Q29: 0 | S29: 0.03
D30: SM-X230/128 ( GRAY ) | N30: GH63-22595A | O30: SM-X400 | P30: GUIA DE CONEXAO PARA CARTAO INTELIGENTE | Q30: SIM TRAY | S30: 0.59
D31: SM-X236B/128 ( GRAY ) | N31: GH63-22595C | O31: SM-X400 | P31: GUIA DE CONEXAO PARA CARTAO INTELIGENTE | Q31: SIM TRAY RED | S31: 0.58
D32: SM-A066M/DS ( GRAY ) | K32: =UPPER(F19) | N32: GH63-22801A | O32: X230 | P32: GUIA DE CONEXAO PARA CARTAO INTELIGENTE | S32: 0.56
D33: SM-A066M/DS ( BLACK ) | K33: =UPPER(F20) | N33: GH68-55255F | O33: X133 | P33: ETIQUETA DE PAPEL AUTO-ADESIVA | Q33: Miudezas | R33: P81N | S33: 0.09
D34: SM-X133/6R4 ( SILVER ) | N34: GH68-56861A | O34: X133 | P34: ETIQUETA DE PLASTICO, AUTO-ADESIVA, EM R | Q34: Miudezas | R34: P81N | S34: 0.03
D35: SM-X135G/6R4 ( GRAY ) | N35: GH68-57610A | O35: X230_X236 | P35: ETIQUETA DE PAPEL, AUTO-ADESIVA, IMPRESS | S35: 0.16
D36: SM-X135G/128 ( GRAY ) | N36: GH69-44361A | O36: SM-A066 | P36: CAIXA DE PAPELAO, ONDULADO. | Q36: CAIXA | R36: P81M | S36: 5.32
D37: SM-X115/64 ( GRAY ) | N37: GH69-45049A | O37: SM-X520/X526 | P37: SACO PARA EMBALAGEM, DE PAPEL. | Q37: BAG | S37: 2.16
N38: GH69-45055A | O38: SM-X620 | P38: SACO PARA EMBALAGEM, DE PAPEL. | Q38: BAG | S38: 2.6
N39: GH69-45272A | O39: SM-X520/X526 | P39: CAIXA DE PAPELAO, ONDULADO. | Q39: CAIXA | S39: 6.84
N40: GH69-45273A | O40: SM-X620/X626 | P40: CAIXA DE PAPELAO, ONDULADO. | Q40: CAIXA | R40: P81L | S40: 7.28
N41: GH69-45618A | O41: SM-X400 | P41: SACO PARA EMBALAGEM, DE PAPEL. | Q41: BAG | S41: 1.51
...

Sheet Revisão 
A3: CONTROLE DE REVISÃO
A4: DATA | B4: REVISÃO | C4: DESCRIÇÃO DA ALTERAÇÃO | D4: ELABORADO POR | E4: APROVADO POR
A5: 45532 | B5: 1A | C5: Elaboração Inicial | D5: Elba Chaves | E5: Leopoldo Jorge
A6: 45978 | B6: 1B | C6: Alteração para modelo ON line | D6: Elba Chaves | E6: Leopoldo Jorge

Sheet IMPRESSAO
A1: Scrap do Dia | L1: =SUBTOTAL(9,L6:L100) -> 0
A5: DATA: | B5: =TODAY() -> 46062 | D5: # | E5: LIDER | F5: MODELO | G5: ITEM | H5: STATUS | J5: QTDE | K5: VUNIT | L5: V TOTAL | M5: CODIGO | N5: DESCRIÇÃO
D6: =IF(E6="","",1) | E6: =IFERROR(INDEX(FORPTB13!$F$4:$F$580,_xlfn.AGGREGATE(15,6,(ROW(FORPTB13!$B$4:$B$580)-ROW(FORPTB13!#REF!)+1)/((FORPTB13!$B$4:$B$580=$B$5)),ROW(FORPTB13!V1))),"") | F6: =IFERROR(INDEX(FORPTB13!$H$4:$H$580,_xlfn.AGGREGATE(15,6,(ROW(FORPTB13!$B$4:$B$580)-ROW(FORPTB13!#REF!)+1)/((FORPTB13!$B$4:$B$580=$B$5)),ROW(FORPTB13!W1))),"") | G6: =IFERROR(INDEX(FORPTB13!$J$4:$J$580,_xlfn.AGGREGATE(15,6,(ROW(FORPTB13!$B$4:$B$580)-ROW(FORPTB13!#REF!)+1)/((FORPTB13!$B$4:$B$580=$B$5)),ROW(FORPTB13!X1))),"") | H6: =IFERROR(INDEX(FORPTB13!$K$4:$K$580,_xlfn.AGGREGATE(15,6,(ROW(FORPTB13!$B$4:$B$580)-ROW(FORPTB13!#REF!)+1)/((FORPTB13!$B$4:$B$580=$B$5)),ROW(FORPTB13!Y1))),"") | I6: =IFERROR(INDEX(FORPTB13!$T$4:$T$580,_xlfn.AGGREGATE(15,6,(ROW(FORPTB13!$B$4:$B$580)-ROW(FORPTB13!#REF!)+1)/((FORPTB13!$B$4:$B$580=$B$5)),ROW(FORPTB13!Z1))),"") | J6: =IFERROR(INDEX(FORPTB13!$I$4:$I$580,_xlfn.AGGREGATE(15,6,(ROW(FORPTB13!$B$4:$B$580)-ROW(FORPTB13!#REF!)+1)/((FORPTB13!$B$4:$B$580=$B$5)),ROW(FORPTB13!Z1))),"") | K6: =IFERROR(INDEX(FORPTB13!$N$4:$N$580,_xlfn.AGGREGATE(15,6,(ROW(FORPTB13!$B$4:$B$580)-ROW(FORPTB13!#REF!)+1)/((FORPTB13!$B$4:$B$580=$B$5)),ROW(FORPTB13!AA1))),"") | L6: =IFERROR(J6*K6," ") | M6: =IFERROR(INDEX(FORPTB13!$L$4:$L$580,_xlfn.AGGREGATE(15,6,(ROW(FORPTB13!$B$4:$B$580)-ROW(FORPTB13!#REF!)+1)/((FORPTB13!$B$4:$B$580=$B$5)),ROW(FORPTB13!AC1))),"") | N6: =IFERROR(INDEX(FORPTB13!$M$4:$M$580,_xlfn.AGGREGATE(15,6,(ROW(FORPTB13!$B$4:$B$580)-ROW(FORPTB13!#REF!)+1)/((FORPTB13!$B$4:$B$580=$B$5)),ROW(FORPTB13!AD1))),"")
D7: =IF(E6="","",D6+1) | E7: =IFERROR(INDEX(FORPTB13!$F$4:$F$580,_xlfn.AGGREGATE(15,6,(ROW(FORPTB13!$B$4:$B$580)-ROW(FORPTB13!#REF!)+1)/((FORPTB13!$B$4:$B$580=$B$5)),ROW(FORPTB13!V2))),"") | F7: =IFERROR(INDEX(FORPTB13!$H$4:$H$580,_xlfn.AGGREGATE(15,6,(ROW(FORPTB13!$B$4:$B$580)-ROW(FORPTB13!#REF!)+1)/((FORPTB13!$B$4:$B$580=$B$5)),ROW(FORPTB13!W2))),"") | G7: =IFERROR(INDEX(FORPTB13!$J$4:$J$580,_xlfn.AGGREGATE(15,6,(ROW(FORPTB13!$B$4:$B$580)-ROW(FORPTB13!#REF!)+1)/((FORPTB13!$B$4:$B$580=$B$5)),ROW(FORPTB13!X2))),"") | H7: =IFERROR(INDEX(FORPTB13!$K$4:$K$580,_xlfn.AGGREGATE(15,6,(ROW(FORPTB13!$B$4:$B$580)-ROW(FORPTB13!#REF!)+1)/((FORPTB13!$B$4:$B$580=$B$5)),ROW(FORPTB13!Y2))),"") | I7: =IFERROR(INDEX(FORPTB13!$T$4:$T$580,_xlfn.AGGREGATE(15,6,(ROW(FORPTB13!$B$4:$B$580)-ROW(FORPTB13!#REF!)+1)/((FORPTB13!$B$4:$B$580=$B$5)),ROW(FORPTB13!Z2))),"") | J7: =IFERROR(INDEX(FORPTB13!$I$4:$I$580,_xlfn.AGGREGATE(15,6,(ROW(FORPTB13!$B$4:$B$580)-ROW(FORPTB13!#REF!)+1)/((FORPTB13!$B$4:$B$580=$B$5)),ROW(FORPTB13!Z2))),"") | K7: =IFERROR(INDEX(FORPTB13!$N$4:$N$580,_xlfn.AGGREGATE(15,6,(ROW(FORPTB13!$B$4:$B$580)-ROW(FORPTB13!#REF!)+1)/((FORPTB13!$B$4:$B$580=$B$5)),ROW(FORPTB13!AA2))),"") | L7: =IFERROR(J7*K7," ") | M7: =IFERROR(INDEX(FORPTB13!$L$4:$L$580,_xlfn.AGGREGATE(15,6,(ROW(FORPTB13!$B$4:$B$580)-ROW(FORPTB13!#REF!)+1)/((FORPTB13!$B$4:$B$580=$B$5)),ROW(FORPTB13!AC2))),"") | N7: =IFERROR(INDEX(FORPTB13!$M$4:$M$580,_xlfn.AGGREGATE(15,6,(ROW(FORPTB13!$B$4:$B$580)-ROW(FORPTB13!#REF!)+1)/((FORPTB13!$B$4:$B$580=$B$5)),ROW(FORPTB13!AD2))),"")
D8: =IF(E7="","",D7+1) | E8: =IFERROR(INDEX(FORPTB13!$F$4:$F$580,_xlfn.AGGREGATE(15,6,(ROW(FORPTB13!$B$4:$B$580)-ROW(FORPTB13!#REF!)+1)/((FORPTB13!$B$4:$B$580=$B$5)),ROW(FORPTB13!V3))),"") | F8: =IFERROR(INDEX(FORPTB13!$H$4:$H$580,_xlfn.AGGREGATE(15,6,(ROW(FORPTB13!$B$4:$B$580)-ROW(FORPTB13!#REF!)+1)/((FORPTB13!$B$4:$B$580=$B$5)),ROW(FORPTB13!W3))),"") | G8: =IFERROR(INDEX(FORPTB13!$J$4:$J$580,_xlfn.AGGREGATE(15,6,(ROW(FORPTB13!$B$4:$B$580)-ROW(FORPTB13!#REF!)+1)/((FORPTB13!$B$4:$B$580=$B$5)),ROW(FORPTB13!X3))),"") | H8: =IFERROR(INDEX(FORPTB13!$K$4:$K$580,_xlfn.AGGREGATE(15,6,(ROW(FORPTB13!$B$4:$B$580)-ROW(FORPTB13!#REF!)+1)/((FORPTB13!$B$4:$B$580=$B$5)),ROW(FORPTB13!Y3))),"") | I8: =IFERROR(INDEX(FORPTB13!$T$4:$T$580,_xlfn.AGGREGATE(15,6,(ROW(FORPTB13!$B$4:$B$580)-ROW(FORPTB13!#REF!)+1)/((FORPTB13!$B$4:$B$580=$B$5)),ROW(FORPTB13!Z3))),"") | J8: =IFERROR(INDEX(FORPTB13!$I$4:$I$580,_xlfn.AGGREGATE(15,6,(ROW(FORPTB13!$B$4:$B$580)-ROW(FORPTB13!#REF!)+1)/((FORPTB13!$B$4:$B$580=$B$5)),ROW(FORPTB13!Z3))),"") | K8: =IFERROR(INDEX(FORPTB13!$N$4:$N$580,_xlfn.AGGREGATE(15,6,(ROW(FORPTB13!$B$4:$B$580)-ROW(FORPTB13!#REF!)+1)/((FORPTB13!$B$4:$B$580=$B$5)),ROW(FORPTB13!AA3))),"") | L8: =IFERROR(J8*K8," ") | M8: =IFERROR(INDEX(FORPTB13!$L$4:$L$580,_xlfn.AGGREGATE(15,6,(ROW(FORPTB13!$B$4:$B$580)-ROW(FORPTB13!#REF!)+1)/((FORPTB13!$B$4:$B$580=$B$5)),ROW(FORPTB13!AC3))),"") | N8: =IFERROR(INDEX(FORPTB13!$M$4:$M$580,_xlfn.AGGREGATE(15,6,(ROW(FORPTB13!$B$4:$B$580)-ROW(FORPTB13!#REF!)+1)/((FORPTB13!$B$4:$B$580=$B$5)),ROW(FORPTB13!AD3))),"")
D9: =IF(D8="","",D8+1) | E9: =IFERROR(INDEX(FORPTB13!$F$4:$F$580,_xlfn.AGGREGATE(15,6,(ROW(FORPTB13!$B$4:$B$580)-ROW(FORPTB13!#REF!)+1)/((FORPTB13!$B$4:$B$580=$B$5)),ROW(FORPTB13!#REF!))),"") | F9: =IFERROR(INDEX(FORPTB13!$H$4:$H$580,_xlfn.AGGREGATE(15,6,(ROW(FORPTB13!$B$4:$B$580)-ROW(FORPTB13!#REF!)+1)/((FORPTB13!$B$4:$B$580=$B$5)),ROW(FORPTB13!#REF!))),"") | G9: =IFERROR(INDEX(FORPTB13!$J$4:$J$580,_xlfn.AGGREGATE(15,6,(ROW(FORPTB13!$B$4:$B$580)-ROW(FORPTB13!#REF!)+1)/((FORPTB13!$B$4:$B$580=$B$5)),ROW(FORPTB13!#REF!))),"") | H9: =IFERROR(INDEX(FORPTB13!$K$4:$K$580,_xlfn.AGGREGATE(15,6,(ROW(FORPTB13!$B$4:$B$580)-ROW(FORPTB13!#REF!)+1)/((FORPTB13!$B$4:$B$580=$B$5)),ROW(FORPTB13!#REF!))),"") | I9: =IFERROR(INDEX(FORPTB13!$T$4:$T$580,_xlfn.AGGREGATE(15,6,(ROW(FORPTB13!$B$4:$B$580)-ROW(FORPTB13!#REF!)+1)/((FORPTB13!$B$4:$B$580=$B$5)),ROW(FORPTB13!#REF!))),"") | J9: =IFERROR(INDEX(FORPTB13!$I$4:$I$580,_xlfn.AGGREGATE(15,6,(ROW(FORPTB13!$B$4:$B$580)-ROW(FORPTB13!#REF!)+1)/((FORPTB13!$B$4:$B$580=$B$5)),ROW(FORPTB13!#REF!))),"") | K9: =IFERROR(INDEX(FORPTB13!$N$4:$N$580,_xlfn.AGGREGATE(15,6,(ROW(FORPTB13!$B$4:$B$580)-ROW(FORPTB13!#REF!)+1)/((FORPTB13!$B$4:$B$580=$B$5)),ROW(FORPTB13!#REF!))),"") | L9: =IFERROR(J9*K9," ") | M9: =IFERROR(INDEX(FORPTB13!$L$4:$L$580,_xlfn.AGGREGATE(15,6,(ROW(FORPTB13!$B$4:$B$580)-ROW(FORPTB13!#REF!)+1)/((FORPTB13!$B$4:$B$580=$B$5)),ROW(FORPTB13!#REF!))),"") | N9: =IFERROR(INDEX(FORPTB13!$M$4:$M$580,_xlfn.AGGREGATE(15,6,(ROW(FORPTB13!$B$4:$B$580)-ROW(FORPTB13!#REF!)+1)/((FORPTB13!$B$4:$B$580=$B$5)),ROW(FORPTB13!#REF!))),"")
D10: =IF(D9="","",D9+1) | E10: =IFERROR(INDEX(FORPTB13!$F$4:$F$580,_xlfn.AGGREGATE(15,6,(ROW(FORPTB13!$B$4:$B$580)-ROW(FORPTB13!#REF!)+1)/((FORPTB13!$B$4:$B$580=$B$5)),ROW(FORPTB13!#REF!))),"") | F10: =IFERROR(INDEX(FORPTB13!$H$4:$H$580,_xlfn.AGGREGATE(15,6,(ROW(FORPTB13!$B$4:$B$580)-ROW(FORPTB13!#REF!)+1)/((FORPTB13!$B$4:$B$580=$B$5)),ROW(FORPTB13!#REF!))),"") | G10: =IFERROR(INDEX(FORPTB13!$J$4:$J$580,_xlfn.AGGREGATE(15,6,(ROW(FORPTB13!$B$4:$B$580)-ROW(FORPTB13!#REF!)+1)/((FORPTB13!$B$4:$B$580=$B$5)),ROW(FORPTB13!#REF!))),"") | H10: =IFERROR(INDEX(FORPTB13!$K$4:$K$580,_xlfn.AGGREGATE(15,6,(ROW(FORPTB13!$B$4:$B$580)-ROW(FORPTB13!#REF!)+1)/((FORPTB13!$B$4:$B$580=$B$5)),ROW(FORPTB13!#REF!))),"") | I10: =IFERROR(INDEX(FORPTB13!$T$4:$T$580,_xlfn.AGGREGATE(15,6,(ROW(FORPTB13!$B$4:$B$580)-ROW(FORPTB13!#REF!)+1)/((FORPTB13!$B$4:$B$580=$B$5)),ROW(FORPTB13!#REF!))),"") | J10: =IFERROR(INDEX(FORPTB13!$I$4:$I$580,_xlfn.AGGREGATE(15,6,(ROW(FORPTB13!$B$4:$B$580)-ROW(FORPTB13!#REF!)+1)/((FORPTB13!$B$4:$B$580=$B$5)),ROW(FORPTB13!#REF!))),"") | K10: =IFERROR(INDEX(FORPTB13!$N$4:$N$580,_xlfn.AGGREGATE(15,6,(ROW(FORPTB13!$B$4:$B$580)-ROW(FORPTB13!#REF!)+1)/((FORPTB13!$B$4:$B$580=$B$5)),ROW(FORPTB13!#REF!))),"") | L10: =IFERROR(J10*K10," ") | M10: =IFERROR(INDEX(FORPTB13!$L$4:$L$580,_xlfn.AGGREGATE(15,6,(ROW(FORPTB13!$B$4:$B$580)-ROW(FORPTB13!#REF!)+1)/((FORPTB13!$B$4:$B$580=$B$5)),ROW(FORPTB13!#REF!))),"") | N10: =IFERROR(INDEX(FORPTB13!$M$4:$M$580,_xlfn.AGGREGATE(15,6,(ROW(FORPTB13!$B$4:$B$580)-ROW(FORPTB13!#REF!)+1)/((FORPTB13!$B$4:$B$580=$B$5)),ROW(FORPTB13!#REF!))),"")
D11: =IF(D10="","",D10+1) | E11: =IFERROR(INDEX(FORPTB13!$F$4:$F$580,_xlfn.AGGREGATE(15,6,(ROW(FORPTB13!$B$4:$B$580)-ROW(FORPTB13!#REF!)+1)/((FORPTB13!$B$4:$B$580=$B$5)),ROW(FORPTB13!#REF!))),"") | F11: =IFERROR(INDEX(FORPTB13!$H$4:$H$580,_xlfn.AGGREGATE(15,6,(ROW(FORPTB13!$B$4:$B$580)-ROW(FORPTB13!#REF!)+1)/((FORPTB13!$B$4:$B$580=$B$5)),ROW(FORPTB13!#REF!))),"") | G11: =IFERROR(INDEX(FORPTB13!$J$4:$J$580,_xlfn.AGGREGATE(15,6,(ROW(FORPTB13!$B$4:$B$580)-ROW(FORPTB13!#REF!)+1)/((FORPTB13!$B$4:$B$580=$B$5)),ROW(FORPTB13!#REF!))),"") | H11: =IFERROR(INDEX(FORPTB13!$K$4:$K$580,_xlfn.AGGREGATE(15,6,(ROW(FORPTB13!$B$4:$B$580)-ROW(FORPTB13!#REF!)+1)/((FORPTB13!$B$4:$B$580=$B$5)),ROW(FORPTB13!#REF!))),"") | I11: =IFERROR(INDEX(FORPTB13!$T$4:$T$580,_xlfn.AGGREGATE(15,6,(ROW(FORPTB13!$B$4:$B$580)-ROW(FORPTB13!#REF!)+1)/((FORPTB13!$B$4:$B$580=$B$5)),ROW(FORPTB13!#REF!))),"") | J11: =IFERROR(INDEX(FORPTB13!$I$4:$I$580,_xlfn.AGGREGATE(15,6,(ROW(FORPTB13!$B$4:$B$580)-ROW(FORPTB13!#REF!)+1)/((FORPTB13!$B$4:$B$580=$B$5)),ROW(FORPTB13!#REF!))),"") | K11: =IFERROR(INDEX(FORPTB13!$N$4:$N$580,_xlfn.AGGREGATE(15,6,(ROW(FORPTB13!$B$4:$B$580)-ROW(FORPTB13!#REF!)+1)/((FORPTB13!$B$4:$B$580=$B$5)),ROW(FORPTB13!#REF!))),"") | L11: =IFERROR(J11*K11," ") | M11: =IFERROR(INDEX(FORPTB13!$L$4:$L$580,_xlfn.AGGREGATE(15,6,(ROW(FORPTB13!$B$4:$B$580)-ROW(FORPTB13!#REF!)+1)/((FORPTB13!$B$4:$B$580=$B$5)),ROW(FORPTB13!#REF!))),"") | N11: =IFERROR(INDEX(FORPTB13!$M$4:$M$580,_xlfn.AGGREGATE(15,6,(ROW(FORPTB13!$B$4:$B$580)-ROW(FORPTB13!#REF!)+1)/((FORPTB13!$B$4:$B$580=$B$5)),ROW(FORPTB13!#REF!))),"")
D12: =IF(D11="","",D11+1) | E12: =IFERROR(INDEX(FORPTB13!$F$4:$F$580,_xlfn.AGGREGATE(15,6,(ROW(FORPTB13!$B$4:$B$580)-ROW(FORPTB13!#REF!)+1)/((FORPTB13!$B$4:$B$580=$B$5)),ROW(FORPTB13!#REF!))),"") | F12: =IFERROR(INDEX(FORPTB13!$H$4:$H$580,_xlfn.AGGREGATE(15,6,(ROW(FORPTB13!$B$4:$B$580)-ROW(FORPTB13!#REF!)+1)/((FORPTB13!$B$4:$B$580=$B$5)),ROW(FORPTB13!#REF!))),"") | G12: =IFERROR(INDEX(FORPTB13!$J$4:$J$580,_xlfn.AGGREGATE(15,6,(ROW(FORPTB13!$B$4:$B$580)-ROW(FORPTB13!#REF!)+1)/((FORPTB13!$B$4:$B$580=$B$5)),ROW(FORPTB13!#REF!))),"") | H12: =IFERROR(INDEX(FORPTB13!$K$4:$K$580,_xlfn.AGGREGATE(15,6,(ROW(FORPTB13!$B$4:$B$580)-ROW(FORPTB13!#REF!)+1)/((FORPTB13!$B$4:$B$580=$B$5)),ROW(FORPTB13!#REF!))),"") | I12: =IFERROR(INDEX(FORPTB13!$T$4:$T$580,_xlfn.AGGREGATE(15,6,(ROW(FORPTB13!$B$4:$B$580)-ROW(FORPTB13!#REF!)+1)/((FORPTB13!$B$4:$B$580=$B$5)),ROW(FORPTB13!#REF!))),"") | J12: =IFERROR(INDEX(FORPTB13!$I$4:$I$580,_xlfn.AGGREGATE(15,6,(ROW(FORPTB13!$B$4:$B$580)-ROW(FORPTB13!#REF!)+1)/((FORPTB13!$B$4:$B$580=$B$5)),ROW(FORPTB13!#REF!))),"") | K12: =IFERROR(INDEX(FORPTB13!$N$4:$N$580,_xlfn.AGGREGATE(15,6,(ROW(FORPTB13!$B$4:$B$580)-ROW(FORPTB13!#REF!)+1)/((FORPTB13!$B$4:$B$580=$B$5)),ROW(FORPTB13!#REF!))),"") | L12: =IFERROR(J12*K12," ") | M12: =IFERROR(INDEX(FORPTB13!$L$4:$L$580,_xlfn.AGGREGATE(15,6,(ROW(FORPTB13!$B$4:$B$580)-ROW(FORPTB13!#REF!)+1)/((FORPTB13!$B$4:$B$580=$B$5)),ROW(FORPTB13!#REF!))),"") | N12: =IFERROR(INDEX(FORPTB13!$M$4:$M$580,_xlfn.AGGREGATE(15,6,(ROW(FORPTB13!$B$4:$B$580)-ROW(FORPTB13!#REF!)+1)/((FORPTB13!$B$4:$B$580=$B$5)),ROW(FORPTB13!#REF!))),"")
D13: =IF(D12="","",D12+1) | E13: =IFERROR(INDEX(FORPTB13!$F$4:$F$580,_xlfn.AGGREGATE(15,6,(ROW(FORPTB13!$B$4:$B$580)-ROW(FORPTB13!#REF!)+1)/((FORPTB13!$B$4:$B$580=$B$5)),ROW(FORPTB13!#REF!))),"") | F13: =IFERROR(INDEX(FORPTB13!$H$4:$H$580,_xlfn.AGGREGATE(15,6,(ROW(FORPTB13!$B$4:$B$580)-ROW(FORPTB13!#REF!)+1)/((FORPTB13!$B$4:$B$580=$B$5)),ROW(FORPTB13!#REF!))),"") | G13: =IFERROR(INDEX(FORPTB13!$J$4:$J$580,_xlfn.AGGREGATE(15,6,(ROW(FORPTB13!$B$4:$B$580)-ROW(FORPTB13!#REF!)+1)/((FORPTB13!$B$4:$B$580=$B$5)),ROW(FORPTB13!#REF!))),"") | H13: =IFERROR(INDEX(FORPTB13!$K$4:$K$580,_xlfn.AGGREGATE(15,6,(ROW(FORPTB13!$B$4:$B$580)-ROW(FORPTB13!#REF!)+1)/((FORPTB13!$B$4:$B$580=$B$5)),ROW(FORPTB13!#REF!))),"") | I13: =IFERROR(INDEX(FORPTB13!$T$4:$T$580,_xlfn.AGGREGATE(15,6,(ROW(FORPTB13!$B$4:$B$580)-ROW(FORPTB13!#REF!)+1)/((FORPTB13!$B$4:$B$580=$B$5)),ROW(FORPTB13!#REF!))),"") | J13: =IFERROR(INDEX(FORPTB13!$I$4:$I$580,_xlfn.AGGREGATE(15,6,(ROW(FORPTB13!$B$4:$B$580)-ROW(FORPTB13!#REF!)+1)/((FORPTB13!$B$4:$B$580=$B$5)),ROW(FORPTB13!#REF!))),"") | K13: =IFERROR(INDEX(FORPTB13!$N$4:$N$580,_xlfn.AGGREGATE(15,6,(ROW(FORPTB13!$B$4:$B$580)-ROW(FORPTB13!#REF!)+1)/((FORPTB13!$B$4:$B$580=$B$5)),ROW(FORPTB13!#REF!))),"") | L13: =IFERROR(J13*K13," ") | M13: =IFERROR(INDEX(FORPTB13!$L$4:$L$580,_xlfn.AGGREGATE(15,6,(ROW(FORPTB13!$B$4:$B$580)-ROW(FORPTB13!#REF!)+1)/((FORPTB13!$B$4:$B$580=$B$5)),ROW(FORPTB13!#REF!))),"") | N13: =IFERROR(INDEX(FORPTB13!$M$4:$M$580,_xlfn.AGGREGATE(15,6,(ROW(FORPTB13!$B$4:$B$580)-ROW(FORPTB13!#REF!)+1)/((FORPTB13!$B$4:$B$580=$B$5)),ROW(FORPTB13!#REF!))),"")
D14: =IF(D13="","",D13+1) | E14: =IFERROR(INDEX(FORPTB13!$F$4:$F$580,_xlfn.AGGREGATE(15,6,(ROW(FORPTB13!$B$4:$B$580)-ROW(FORPTB13!#REF!)+1)/((FORPTB13!$B$4:$B$580=$B$5)),ROW(FORPTB13!#REF!))),"") | F14: =IFERROR(INDEX(FORPTB13!$H$4:$H$580,_xlfn.AGGREGATE(15,6,(ROW(FORPTB13!$B$4:$B$580)-ROW(FORPTB13!#REF!)+1)/((FORPTB13!$B$4:$B$580=$B$5)),ROW(FORPTB13!#REF!))),"") | G14: =IFERROR(INDEX(FORPTB13!$J$4:$J$580,_xlfn.AGGREGATE(15,6,(ROW(FORPTB13!$B$4:$B$580)-ROW(FORPTB13!#REF!)+1)/((FORPTB13!$B$4:$B$580=$B$5)),ROW(FORPTB13!#REF!))),"") | H14: =IFERROR(INDEX(FORPTB13!$K$4:$K$580,_xlfn.AGGREGATE(15,6,(ROW(FORPTB13!$B$4:$B$580)-ROW(FORPTB13!#REF!)+1)/((FORPTB13!$B$4:$B$580=$B$5)),ROW(FORPTB13!#REF!))),"") | I14: =IFERROR(INDEX(FORPTB13!$T$4:$T$580,_xlfn.AGGREGATE(15,6,(ROW(FORPTB13!$B$4:$B$580)-ROW(FORPTB13!#REF!)+1)/((FORPTB13!$B$4:$B$580=$B$5)),ROW(FORPTB13!#REF!))),"") | J14: =IFERROR(INDEX(FORPTB13!$I$4:$I$580,_xlfn.AGGREGATE(15,6,(ROW(FORPTB13!$B$4:$B$580)-ROW(FORPTB13!#REF!)+1)/((FORPTB13!$B$4:$B$580=$B$5)),ROW(FORPTB13!#REF!))),"") | K14: =IFERROR(INDEX(FORPTB13!$N$4:$N$580,_xlfn.AGGREGATE(15,6,(ROW(FORPTB13!$B$4:$B$580)-ROW(FORPTB13!#REF!)+1)/((FORPTB13!$B$4:$B$580=$B$5)),ROW(FORPTB13!#REF!))),"") | L14: =IFERROR(J14*K14," ") | M14: =IFERROR(INDEX(FORPTB13!$L$4:$L$580,_xlfn.AGGREGATE(15,6,(ROW(FORPTB13!$B$4:$B$580)-ROW(FORPTB13!#REF!)+1)/((FORPTB13!$B$4:$B$580=$B$5)),ROW(FORPTB13!#REF!))),"") | N14: =IFERROR(INDEX(FORPTB13!$M$4:$M$580,_xlfn.AGGREGATE(15,6,(ROW(FORPTB13!$B$4:$B$580)-ROW(FORPTB13!#REF!)+1)/((FORPTB13!$B$4:$B$580=$B$5)),ROW(FORPTB13!#REF!))),"")
D15: =IF(D14="","",D14+1) | E15: =IFERROR(INDEX(FORPTB13!$F$4:$F$580,_xlfn.AGGREGATE(15,6,(ROW(FORPTB13!$B$4:$B$580)-ROW(FORPTB13!#REF!)+1)/((FORPTB13!$B$4:$B$580=$B$5)),ROW(FORPTB13!#REF!))),"") | F15: =IFERROR(INDEX(FORPTB13!$H$4:$H$580,_xlfn.AGGREGATE(15,6,(ROW(FORPTB13!$B$4:$B$580)-ROW(FORPTB13!#REF!)+1)/((FORPTB13!$B$4:$B$580=$B$5)),ROW(FORPTB13!#REF!))),"") | G15: =IFERROR(INDEX(FORPTB13!$J$4:$J$580,_xlfn.AGGREGATE(15,6,(ROW(FORPTB13!$B$4:$B$580)-ROW(FORPTB13!#REF!)+1)/((FORPTB13!$B$4:$B$580=$B$5)),ROW(FORPTB13!#REF!))),"") | H15: =IFERROR(INDEX(FORPTB13!$K$4:$K$580,_xlfn.AGGREGATE(15,6,(ROW(FORPTB13!$B$4:$B$580)-ROW(FORPTB13!#REF!)+1)/((FORPTB13!$B$4:$B$580=$B$5)),ROW(FORPTB13!#REF!))),"") | I15: =IFERROR(INDEX(FORPTB13!$T$4:$T$580,_xlfn.AGGREGATE(15,6,(ROW(FORPTB13!$B$4:$B$580)-ROW(FORPTB13!#REF!)+1)/((FORPTB13!$B$4:$B$580=$B$5)),ROW(FORPTB13!#REF!))),"") | J15: =IFERROR(INDEX(FORPTB13!$I$4:$I$580,_xlfn.AGGREGATE(15,6,(ROW(FORPTB13!$B$4:$B$580)-ROW(FORPTB13!#REF!)+1)/((FORPTB13!$B$4:$B$580=$B$5)),ROW(FORPTB13!#REF!))),"") | K15: =IFERROR(INDEX(FORPTB13!$N$4:$N$580,_xlfn.AGGREGATE(15,6,(ROW(FORPTB13!$B$4:$B$580)-ROW(FORPTB13!#REF!)+1)/((FORPTB13!$B$4:$B$580=$B$5)),ROW(FORPTB13!#REF!))),"") | L15: =IFERROR(J15*K15," ") | M15: =IFERROR(INDEX(FORPTB13!$L$4:$L$580,_xlfn.AGGREGATE(15,6,(ROW(FORPTB13!$B$4:$B$580)-ROW(FORPTB13!#REF!)+1)/((FORPTB13!$B$4:$B$580=$B$5)),ROW(FORPTB13!#REF!))),"") | N15: =IFERROR(INDEX(FORPTB13!$M$4:$M$580,_xlfn.AGGREGATE(15,6,(ROW(FORPTB13!$B$4:$B$580)-ROW(FORPTB13!#REF!)+1)/((FORPTB13!$B$4:$B$580=$B$5)),ROW(FORPTB13!#REF!))),"")
D16: =IF(D15="","",D15+1) | E16: =IFERROR(INDEX(FORPTB13!$F$4:$F$580,_xlfn.AGGREGATE(15,6,(ROW(FORPTB13!$B$4:$B$580)-ROW(FORPTB13!#REF!)+1)/((FORPTB13!$B$4:$B$580=$B$5)),ROW(FORPTB13!#REF!))),"") | F16: =IFERROR(INDEX(FORPTB13!$H$4:$H$580,_xlfn.AGGREGATE(15,6,(ROW(FORPTB13!$B$4:$B$580)-ROW(FORPTB13!#REF!)+1)/((FORPTB13!$B$4:$B$580=$B$5)),ROW(FORPTB13!#REF!))),"") | G16: =IFERROR(INDEX(FORPTB13!$J$4:$J$580,_xlfn.AGGREGATE(15,6,(ROW(FORPTB13!$B$4:$B$580)-ROW(FORPTB13!#REF!)+1)/((FORPTB13!$B$4:$B$580=$B$5)),ROW(FORPTB13!#REF!))),"") | H16: =IFERROR(INDEX(FORPTB13!$K$4:$K$580,_xlfn.AGGREGATE(15,6,(ROW(FORPTB13!$B$4:$B$580)-ROW(FORPTB13!#REF!)+1)/((FORPTB13!$B$4:$B$580=$B$5)),ROW(FORPTB13!#REF!))),"") | I16: =IFERROR(INDEX(FORPTB13!$T$4:$T$580,_xlfn.AGGREGATE(15,6,(ROW(FORPTB13!$B$4:$B$580)-ROW(FORPTB13!#REF!)+1)/((FORPTB13!$B$4:$B$580=$B$5)),ROW(FORPTB13!#REF!))),"") | J16: =IFERROR(INDEX(FORPTB13!$I$4:$I$580,_xlfn.AGGREGATE(15,6,(ROW(FORPTB13!$B$4:$B$580)-ROW(FORPTB13!#REF!)+1)/((FORPTB13!$B$4:$B$580=$B$5)),ROW(FORPTB13!#REF!))),"") | K16: =IFERROR(INDEX(FORPTB13!$N$4:$N$580,_xlfn.AGGREGATE(15,6,(ROW(FORPTB13!$B$4:$B$580)-ROW(FORPTB13!#REF!)+1)/((FORPTB13!$B$4:$B$580=$B$5)),ROW(FORPTB13!#REF!))),"") | L16: =IFERROR(J16*K16," ") | M16: =IFERROR(INDEX(FORPTB13!$L$4:$L$580,_xlfn.AGGREGATE(15,6,(ROW(FORPTB13!$B$4:$B$580)-ROW(FORPTB13!#REF!)+1)/((FORPTB13!$B$4:$B$580=$B$5)),ROW(FORPTB13!#REF!))),"") | N16: =IFERROR(INDEX(FORPTB13!$M$4:$M$580,_xlfn.AGGREGATE(15,6,(ROW(FORPTB13!$B$4:$B$580)-ROW(FORPTB13!#REF!)+1)/((FORPTB13!$B$4:$B$580=$B$5)),ROW(FORPTB13!#REF!))),"")
D17: =IF(D16="","",D16+1) | E17: =IFERROR(INDEX(FORPTB13!$F$4:$F$580,_xlfn.AGGREGATE(15,6,(ROW(FORPTB13!$B$4:$B$580)-ROW(FORPTB13!#REF!)+1)/((FORPTB13!$B$4:$B$580=$B$5)),ROW(FORPTB13!#REF!))),"") | F17: =IFERROR(INDEX(FORPTB13!$H$4:$H$580,_xlfn.AGGREGATE(15,6,(ROW(FORPTB13!$B$4:$B$580)-ROW(FORPTB13!#REF!)+1)/((FORPTB13!$B$4:$B$580=$B$5)),ROW(FORPTB13!#REF!))),"") | G17: =IFERROR(INDEX(FORPTB13!$J$4:$J$580,_xlfn.AGGREGATE(15,6,(ROW(FORPTB13!$B$4:$B$580)-ROW(FORPTB13!#REF!)+1)/((FORPTB13!$B$4:$B$580=$B$5)),ROW(FORPTB13!#REF!))),"") | H17: =IFERROR(INDEX(FORPTB13!$K$4:$K$580,_xlfn.AGGREGATE(15,6,(ROW(FORPTB13!$B$4:$B$580)-ROW(FORPTB13!#REF!)+1)/((FORPTB13!$B$4:$B$580=$B$5)),ROW(FORPTB13!#REF!))),"") | I17: =IFERROR(INDEX(FORPTB13!$T$4:$T$580,_xlfn.AGGREGATE(15,6,(ROW(FORPTB13!$B$4:$B$580)-ROW(FORPTB13!#REF!)+1)/((FORPTB13!$B$4:$B$580=$B$5)),ROW(FORPTB13!#REF!))),"") | J17: =IFERROR(INDEX(FORPTB13!$I$4:$I$580,_xlfn.AGGREGATE(15,6,(ROW(FORPTB13!$B$4:$B$580)-ROW(FORPTB13!#REF!)+1)/((FORPTB13!$B$4:$B$580=$B$5)),ROW(FORPTB13!#REF!))),"") | K17: =IFERROR(INDEX(FORPTB13!$N$4:$N$580,_xlfn.AGGREGATE(15,6,(ROW(FORPTB13!$B$4:$B$580)-ROW(FORPTB13!#REF!)+1)/((FORPTB13!$B$4:$B$580=$B$5)),ROW(FORPTB13!#REF!))),"") | L17: =IFERROR(J17*K17," ") | M17: =IFERROR(INDEX(FORPTB13!$L$4:$L$580,_xlfn.AGGREGATE(15,6,(ROW(FORPTB13!$B$4:$B$580)-ROW(FORPTB13!#REF!)+1)/((FORPTB13!$B$4:$B$580=$B$5)),ROW(FORPTB13!#REF!))),"") | N17: =IFERROR(INDEX(FORPTB13!$M$4:$M$580,_xlfn.AGGREGATE(15,6,(ROW(FORPTB13!$B$4:$B$580)-ROW(FORPTB13!#REF!)+1)/((FORPTB13!$B$4:$B$580=$B$5)),ROW(FORPTB13!#REF!))),"")
D18: =IF(D17="","",D17+1) | E18: =IFERROR(INDEX(FORPTB13!$F$4:$F$580,_xlfn.AGGREGATE(15,6,(ROW(FORPTB13!$B$4:$B$580)-ROW(FORPTB13!#REF!)+1)/((FORPTB13!$B$4:$B$580=$B$5)),ROW(FORPTB13!#REF!))),"") | F18: =IFERROR(INDEX(FORPTB13!$H$4:$H$580,_xlfn.AGGREGATE(15,6,(ROW(FORPTB13!$B$4:$B$580)-ROW(FORPTB13!#REF!)+1)/((FORPTB13!$B$4:$B$580=$B$5)),ROW(FORPTB13!#REF!))),"") | G18: =IFERROR(INDEX(FORPTB13!$J$4:$J$580,_xlfn.AGGREGATE(15,6,(ROW(FORPTB13!$B$4:$B$580)-ROW(FORPTB13!#REF!)+1)/((FORPTB13!$B$4:$B$580=$B$5)),ROW(FORPTB13!#REF!))),"") | H18: =IFERROR(INDEX(FORPTB13!$K$4:$K$580,_xlfn.AGGREGATE(15,6,(ROW(FORPTB13!$B$4:$B$580)-ROW(FORPTB13!#REF!)+1)/((FORPTB13!$B$4:$B$580=$B$5)),ROW(FORPTB13!#REF!))),"") | I18: =IFERROR(INDEX(FORPTB13!$T$4:$T$580,_xlfn.AGGREGATE(15,6,(ROW(FORPTB13!$B$4:$B$580)-ROW(FORPTB13!#REF!)+1)/((FORPTB13!$B$4:$B$580=$B$5)),ROW(FORPTB13!#REF!))),"") | J18: =IFERROR(INDEX(FORPTB13!$I$4:$I$580,_xlfn.AGGREGATE(15,6,(ROW(FORPTB13!$B$4:$B$580)-ROW(FORPTB13!#REF!)+1)/((FORPTB13!$B$4:$B$580=$B$5)),ROW(FORPTB13!#REF!))),"") | K18: =IFERROR(INDEX(FORPTB13!$N$4:$N$580,_xlfn.AGGREGATE(15,6,(ROW(FORPTB13!$B$4:$B$580)-ROW(FORPTB13!#REF!)+1)/((FORPTB13!$B$4:$B$580=$B$5)),ROW(FORPTB13!#REF!))),"") | L18: =IFERROR(J18*K18," ") | M18: =IFERROR(INDEX(FORPTB13!$L$4:$L$580,_xlfn.AGGREGATE(15,6,(ROW(FORPTB13!$B$4:$B$580)-ROW(FORPTB13!#REF!)+1)/((FORPTB13!$B$4:$B$580=$B$5)),ROW(FORPTB13!#REF!))),"") | N18: =IFERROR(INDEX(FORPTB13!$M$4:$M$580,_xlfn.AGGREGATE(15,6,(ROW(FORPTB13!$B$4:$B$580)-ROW(FORPTB13!#REF!)+1)/((FORPTB13!$B$4:$B$580=$B$5)),ROW(FORPTB13!#REF!))),"")
D19: =IF(D18="","",D18+1) | E19: =IFERROR(INDEX(FORPTB13!$F$4:$F$580,_xlfn.AGGREGATE(15,6,(ROW(FORPTB13!$B$4:$B$580)-ROW(FORPTB13!#REF!)+1)/((FORPTB13!$B$4:$B$580=$B$5)),ROW(FORPTB13!#REF!))),"") | F19: =IFERROR(INDEX(FORPTB13!$H$4:$H$580,_xlfn.AGGREGATE(15,6,(ROW(FORPTB13!$B$4:$B$580)-ROW(FORPTB13!#REF!)+1)/((FORPTB13!$B$4:$B$580=$B$5)),ROW(FORPTB13!#REF!))),"") | G19: =IFERROR(INDEX(FORPTB13!$J$4:$J$580,_xlfn.AGGREGATE(15,6,(ROW(FORPTB13!$B$4:$B$580)-ROW(FORPTB13!#REF!)+1)/((FORPTB13!$B$4:$B$580=$B$5)),ROW(FORPTB13!#REF!))),"") | H19: =IFERROR(INDEX(FORPTB13!$K$4:$K$580,_xlfn.AGGREGATE(15,6,(ROW(FORPTB13!$B$4:$B$580)-ROW(FORPTB13!#REF!)+1)/((FORPTB13!$B$4:$B$580=$B$5)),ROW(FORPTB13!#REF!))),"") | I19: =IFERROR(INDEX(FORPTB13!$T$4:$T$580,_xlfn.AGGREGATE(15,6,(ROW(FORPTB13!$B$4:$B$580)-ROW(FORPTB13!#REF!)+1)/((FORPTB13!$B$4:$B$580=$B$5)),ROW(FORPTB13!#REF!))),"") | J19: =IFERROR(INDEX(FORPTB13!$I$4:$I$580,_xlfn.AGGREGATE(15,6,(ROW(FORPTB13!$B$4:$B$580)-ROW(FORPTB13!#REF!)+1)/((FORPTB13!$B$4:$B$580=$B$5)),ROW(FORPTB13!#REF!))),"") | K19: =IFERROR(INDEX(FORPTB13!$N$4:$N$580,_xlfn.AGGREGATE(15,6,(ROW(FORPTB13!$B$4:$B$580)-ROW(FORPTB13!#REF!)+1)/((FORPTB13!$B$4:$B$580=$B$5)),ROW(FORPTB13!#REF!))),"") | L19: =IFERROR(J19*K19," ") | M19: =IFERROR(INDEX(FORPTB13!$L$4:$L$580,_xlfn.AGGREGATE(15,6,(ROW(FORPTB13!$B$4:$B$580)-ROW(FORPTB13!#REF!)+1)/((FORPTB13!$B$4:$B$580=$B$5)),ROW(FORPTB13!#REF!))),"") | N19: =IFERROR(INDEX(FORPTB13!$M$4:$M$580,_xlfn.AGGREGATE(15,6,(ROW(FORPTB13!$B$4:$B$580)-ROW(FORPTB13!#REF!)+1)/((FORPTB13!$B$4:$B$580=$B$5)),ROW(FORPTB13!#REF!))),"")
D20: =IF(D19="","",D19+1) | E20: =IFERROR(INDEX(FORPTB13!$F$4:$F$580,_xlfn.AGGREGATE(15,6,(ROW(FORPTB13!$B$4:$B$580)-ROW(FORPTB13!#REF!)+1)/((FORPTB13!$B$4:$B$580=$B$5)),ROW(FORPTB13!#REF!))),"") | F20: =IFERROR(INDEX(FORPTB13!$H$4:$H$580,_xlfn.AGGREGATE(15,6,(ROW(FORPTB13!$B$4:$B$580)-ROW(FORPTB13!#REF!)+1)/((FORPTB13!$B$4:$B$580=$B$5)),ROW(FORPTB13!#REF!))),"") | G20: =IFERROR(INDEX(FORPTB13!$J$4:$J$580,_xlfn.AGGREGATE(15,6,(ROW(FORPTB13!$B$4:$B$580)-ROW(FORPTB13!#REF!)+1)/((FORPTB13!$B$4:$B$580=$B$5)),ROW(FORPTB13!#REF!))),"") | H20: =IFERROR(INDEX(FORPTB13!$K$4:$K$580,_xlfn.AGGREGATE(15,6,(ROW(FORPTB13!$B$4:$B$580)-ROW(FORPTB13!#REF!)+1)/((FORPTB13!$B$4:$B$580=$B$5)),ROW(FORPTB13!#REF!))),"") | I20: =IFERROR(INDEX(FORPTB13!$T$4:$T$580,_xlfn.AGGREGATE(15,6,(ROW(FORPTB13!$B$4:$B$580)-ROW(FORPTB13!#REF!)+1)/((FORPTB13!$B$4:$B$580=$B$5)),ROW(FORPTB13!#REF!))),"") | J20: =IFERROR(INDEX(FORPTB13!$I$4:$I$580,_xlfn.AGGREGATE(15,6,(ROW(FORPTB13!$B$4:$B$580)-ROW(FORPTB13!#REF!)+1)/((FORPTB13!$B$4:$B$580=$B$5)),ROW(FORPTB13!#REF!))),"") | K20: =IFERROR(INDEX(FORPTB13!$N$4:$N$580,_xlfn.AGGREGATE(15,6,(ROW(FORPTB13!$B$4:$B$580)-ROW(FORPTB13!#REF!)+1)/((FORPTB13!$B$4:$B$580=$B$5)),ROW(FORPTB13!#REF!))),"") | L20: =IFERROR(J20*K20," ") | M20: =IFERROR(INDEX(FORPTB13!$L$4:$L$580,_xlfn.AGGREGATE(15,6,(ROW(FORPTB13!$B$4:$B$580)-ROW(FORPTB13!#REF!)+1)/((FORPTB13!$B$4:$B$580=$B$5)),ROW(FORPTB13!#REF!))),"") | N20: =IFERROR(INDEX(FORPTB13!$M$4:$M$580,_xlfn.AGGREGATE(15,6,(ROW(FORPTB13!$B$4:$B$580)-ROW(FORPTB13!#REF!)+1)/((FORPTB13!$B$4:$B$580=$B$5)),ROW(FORPTB13!#REF!))),"")
... D100: =IF(D99="","",D99+1) | E100: =IFERROR(INDEX(FORPTB13!$F$4:$F$580,_xlfn.AGGREGATE(15,6,(ROW(FORPTB13!$B$4:$B$580)-ROW(FORPTB13!#REF!)+1)/((FORPTB13!$B$4:$B$580=$B$5)),ROW(FORPTB13!#REF!))),"") | F100: =IFERROR(INDEX(FORPTB13!$H$4:$H$580,_xlfn.AGGREGATE(15,6,(ROW(FORPTB13!$B$4:$B$580)-ROW(FORPTB13!#REF!)+1)/((FORPTB13!$B$4:$B$580=$B$5)),ROW(FORPTB13!#REF!))),"") | G100: =IFERROR(INDEX(FORPTB13!$J$4:$J$580,_xlfn.AGGREGATE(15,6,(ROW(FORPTB13!$B$4:$B$580)-ROW(FORPTB13!#REF!)+1)/((FORPTB13!$B$4:$B$580=$B$5)),ROW(FORPTB13!#REF!))),"") | H100: =IFERROR(INDEX(FORPTB13!$K$4:$K$580,_xlfn.AGGREGATE(15,6,(ROW(FORPTB13!$B$4:$B$580)-ROW(FORPTB13!#REF!)+1)/((FORPTB13!$B$4:$B$580=$B$5)),ROW(FORPTB13!#REF!))),"") | I100: =IFERROR(INDEX(FORPTB13!$T$4:$T$580,_xlfn.AGGREGATE(15,6,(ROW(FORPTB13!$B$4:$B$580)-ROW(FORPTB13!#REF!)+1)/((FORPTB13!$B$4:$B$580=$B$5)),ROW(FORPTB13!#REF!))),"") | J100: =IFERROR(INDEX(FORPTB13!$I$4:$I$580,_xlfn.AGGREGATE(15,6,(ROW(FORPTB13!$B$4:$B$580)-ROW(FORPTB13!#REF!)+1)/((FORPTB13!$B$4:$B$580=$B$5)),ROW(FORPTB13!#REF!))),"") | K100: =IFERROR(INDEX(FORPTB13!$N$4:$N$580,_xlfn.AGGREGATE(15,6,(ROW(FORPTB13!$B$4:$B$580)-ROW(FORPTB13!#REF!)+1)/((FORPTB13!$B$4:$B$580=$B$5)),ROW(FORPTB13!#REF!))),"") | L100: =IFERROR(J100*K100," ") | M100: =IFERROR(INDEX(FORPTB13!$L$4:$L$580,_xlfn.AGGREGATE(15,6,(ROW(FORPTB13!$B$4:$B$580)-ROW(FORPTB13!#REF!)+1)/((FORPTB13!$B$4:$B$580=$B$5)),ROW(FORPTB13!#REF!))),"") | N100: =IFERROR(INDEX(FORPTB13!$M$4:$M$580,_xlfn.AGGREGATE(15,6,(ROW(FORPTB13!$B$4:$B$580)-ROW(FORPTB13!#REF!)+1)/((FORPTB13!$B$4:$B$580=$B$5)),ROW(FORPTB13!#REF!))),"")
